<testsuite errors="0" failures="1" name="Django Project Tests" skips="0" tests="8" time="0.025"><testcase classname="contacts.test.test_forms.TestContactForm" name="test_contact_form_has_fields" time="0.000648" /><testcase classname="contacts.test.test_forms.TestContactForm" name="test_meta_settings" time="0.000486" /><testcase classname="contacts.test.test_forms.TestContactPhotoForm" name="test_clean_photo" time="0.005536" /><testcase classname="contacts.test.test_forms.TestContactPhotoForm" name="test_clean_photo_large" time="0.004678" /><testcase classname="contacts.test.test_forms.TestContactPhotoForm" name="test_meta_settings" time="0.000079" /><testcase classname="contacts.test.test_forms.TestImportFileFolderForm" name="test_clean_form_with_large_archive" time="0.000729"><failure message="False is not true" type="builtins.AssertionError">Traceback (most recent call last):
  File "/home/forward/.virtualenvs/mycontacts/contacts/test/test_forms.py", line 86, in test_clean_form_with_large_archive
    self.assertTrue(form.is_valid())
AssertionError: False is not true
</failure></testcase><testcase classname="contacts.test.test_forms.TestImportFileFolderForm" name="test_form_has_fields" time="0.000273" /><testcase classname="contacts.test.test_forms.TestUserSignUpForm" name="test_form_has_fields" time="0.000400" /></testsuite>